<?xml version="1.0" encoding="utf-8"?>
<!-- This URDF was automatically created by SolidWorks to URDF Exporter! Originally created by
Stephen Brawner (brawner@gmail.com) 
     Commit Version: 1.6.0-4-g7f85cfe  Build Version: 1.6.7995.38578
     For more information, please see http://wiki.ros.org/sw_urdf_exporter -->
<robot
  name="go2_arx_description">
  <link
    name="trunk">
    <inertial>
      <origin
        xyz="0.021112 0 -0.005366"
        rpy="0 0 0" />
      <mass
        value="6.921" />
      <inertia
        ixx="0.02448"
        ixy="0.00012166"
        ixz="0.0014849"
        iyy="0.098077"
        iyz="-3.12E-05"
        izz="0.107" />
    </inertial>
    <visual>
      <origin
        xyz="0 0 0"
        rpy="0 0 0" />
      <geometry>
        <mesh
          filename="../meshes/base.dae" />
      </geometry>
      <material
        name="">
        <color
          rgba="1 1 1 1" />
      </material>
    </visual>
    <collision>
      <origin rpy="0 0 0" xyz="0 0 0" />
      <geometry>
        <box size="0.3762 0.0935 0.114" />
      </geometry>
    </collision>
  </link>
  <link
    name="Head_upper">
    <inertial>
      <origin
        xyz="0 0 0"
        rpy="0 0 0" />
      <mass
        value="0.001" />
      <inertia
        ixx="9.6e-06"
        ixy="0"
        ixz="0"
        iyy="9.6e-06"
        iyz="0"
        izz="9.6e-06" />
    </inertial>
    <collision>
      <origin
        xyz="0 0 0"
        rpy="0 0 0" />
      <geometry>
        <cylinder radius="0.05" length="0.09" />
      </geometry>
    </collision>
  </link>
  <joint
    name="Head_upper_joint"
    type="fixed" >
    <origin
      xyz="0.285 0 0.01"
      rpy="0 0 0" />
    <parent
      link="trunk" />
    <child
      link="Head_upper" />
    <axis
      xyz="0 0 0" />
  </joint>
  <link
    name="Head_lower">
    <inertial>
      <origin
        xyz="0 0 0"
        rpy="0 0 0" />
      <mass
        value="0.001" />
      <inertia
        ixx="9.6e-06"
        ixy="0"
        ixz="0"
        iyy="9.6e-06"
        iyz="0"
        izz="9.6e-06" />
    </inertial>
    <collision>
      <origin
        xyz="0 0 0"
        rpy="0 0 0" />
      <geometry>
        <sphere radius="0.047" />
      </geometry>
    </collision>
  </link>
  <joint
    name="Head_lower_joint"
    type="fixed" >
    <origin
      xyz="0.008 0 -0.07"
      rpy="0 0 0" />
    <parent
      link="Head_upper" />
    <child
      link="Head_lower" />
    <axis
      xyz="0 0 0" />
  </joint>
  <link
    name="FL_hip">
    <inertial>
      <origin
        xyz="-0.0054 0.00194 -0.000105"
        rpy="0 0 0" />
      <mass
        value="0.678" />
      <inertia
        ixx="0.00048"
        ixy="-3.01E-06"
        ixz="1.11E-06"
        iyy="0.000884"
        iyz="-1.42E-06"
        izz="0.000596" />
    </inertial>
    <visual>
      <origin
        xyz="0 0 0"
        rpy="0 0 0" />
      <geometry>
        <mesh
          filename="../meshes/hip.dae" />
      </geometry>
      <material
        name="">
        <color
          rgba="1 1 1 1" />
      </material>
    </visual>
    <collision>
      <origin rpy="1.5707963267948966 0 0" xyz="0 0.08 0" />
      <geometry>
        <cylinder length="0.04" radius="0.046" />
      </geometry>
    </collision>
  </link>
  <joint
    name="FL_hip_joint"
    type="revolute">
    <origin
      xyz="0.1934 0.0465 0"
      rpy="0 0 0" />
    <parent
      link="trunk" />
    <child
      link="FL_hip" />
    <axis
      xyz="1 0 0" />
    <limit
      lower="-1.0472"
      upper="1.0472"
      effort="23.7"
      velocity="30.1" />
  </joint>
  <link
    name="FL_thigh">
    <inertial>
      <origin
        xyz="-0.00374 -0.0223 -0.0327"
        rpy="0 0 0" />
      <mass
        value="1.152" />
      <inertia
        ixx="0.00584"
        ixy="8.72E-05"
        ixz="-0.000289"
        iyy="0.0058"
        iyz="0.000808"
        izz="0.00103" />
    </inertial>
    <visual>
      <origin
        xyz="0 0 0"
        rpy="0 0 0" />
      <geometry>
        <mesh
          filename="../meshes/thigh.dae" />
      </geometry>
      <material
        name="">
        <color
          rgba="1 1 1 1" />
      </material>
    </visual>
    <collision>
      <origin rpy="0 1.5707963267948966 0" xyz="0 0 -0.1065" />
      <geometry>
        <box size="0.11 0.0245 0.034" />
      </geometry>
    </collision>
  </link>
  <joint
    name="FL_thigh_joint"
    type="revolute">
    <origin
      xyz="0 0.0955 0"
      rpy="0 0 0" />
    <parent
      link="FL_hip" />
    <child
      link="FL_thigh" />
    <axis
      xyz="0 1 0" />
    <limit
      lower="-1.5708"
      upper="3.4907"
      effort="23.7"
      velocity="30.1" />
  </joint>
  <link
    name="FL_calf">
    <inertial>
      <origin
        xyz="0.00548 -0.000975 -0.115"
        rpy="0 0 0" />
      <mass
        value="0.154" />
      <inertia
        ixx="0.00108"
        ixy="3.4E-07"
        ixz="1.72E-05"
        iyy="0.0011"
        iyz="8.28E-06"
        izz="3.29E-05" />
    </inertial>
    <visual>
      <origin
        xyz="0 0 0"
        rpy="0 0 0" />
      <geometry>
        <mesh
          filename="../meshes/calf.dae" />
      </geometry>
      <material
        name="">
        <color
          rgba="1 1 1 1" />
      </material>
    </visual>
    <collision>
      <origin rpy="0 -0.21 0" xyz="0.008 0 -0.06" />
      <geometry>
        <cylinder length="0.12" radius="0.012" />
      </geometry>
    </collision>
  </link>
  <joint
    name="FL_calf_joint"
    type="revolute">
    <origin
      xyz="0 0 -0.213"
      rpy="0 0 0" />
    <parent
      link="FL_thigh" />
    <child
      link="FL_calf" />
    <axis
      xyz="0 1 0" />
    <limit
      lower="-2.7227"
      upper="-0.83776"
      effort="35.55"
      velocity="20.07" />
  </joint>
  <link
    name="FL_calflower">
    <collision>
      <origin rpy="0 0 0" xyz="0 0 0" />
      <geometry>
        <cylinder length="0.065" radius="0.011" />
      </geometry>
    </collision>
  </link>
  <joint
    name="FL_calflower_joint"
    type="fixed">
    <origin
      xyz="0.020 0 -0.148"
      rpy="0 0.05 0" />
    <parent
      link="FL_calf" />
    <child
      link="FL_calflower" />
    <axis
      xyz="0 0 0" />
  </joint>
  <link
    name="FL_calflower1">
    <collision>
      <origin rpy="0 0 0" xyz="0 0 0" />
      <geometry>
        <cylinder length="0.03" radius="0.0155" />
      </geometry>
    </collision>
  </link>
  <joint
    name="FL_calflower1_joint"
    type="fixed">
    <origin
      xyz="-0.01 0 -0.04"
      rpy="0 0.48 0" />
    <parent
      link="FL_calflower" />
    <child
      link="FL_calflower1" />
    <axis
      xyz="0 0 0" />
  </joint>
  <link
    name="FL_foot">
    <inertial>
      <origin
        xyz="0 0 0"
        rpy="0 0 0" />
      <mass
        value="0.04" />
      <inertia
        ixx="9.6e-06"
        ixy="0"
        ixz="0"
        iyy="9.6e-06"
        iyz="0"
        izz="9.6e-06" />
    </inertial>
    <visual>
      <origin
        xyz="0 0 0"
        rpy="0 0 0" />
      <geometry>
        <mesh
          filename="../meshes/foot.dae" />
      </geometry>
      <material
        name="">
        <color
          rgba="1 1 1 1" />
      </material>
    </visual>
    <collision>
      <origin rpy="0 0 0" xyz="-0.002 0 0" />
      <geometry>
        <sphere radius="0.022" />
      </geometry>
    </collision>
  </link>
  <joint
    name="FL_foot_joint"
    type="fixed" >
    <origin
      xyz="0 0 -0.213"
      rpy="0 0 0" />
    <parent
      link="FL_calf" />
    <child
      link="FL_foot" />
    <axis
      xyz="0 0 0" />
  </joint>
  <link
    name="FR_hip">
    <inertial>
      <origin
        xyz="-0.0054 -0.00194 -0.000105"
        rpy="0 0 0" />
      <mass
        value="0.678" />
      <inertia
        ixx="0.00048"
        ixy="3.01E-06"
        ixz="1.11E-06"
        iyy="0.000884"
        iyz="1.42E-06"
        izz="0.000596" />
    </inertial>
    <visual>
      <origin
        xyz="0 0 0"
        rpy="3.1415 0 0" />
      <geometry>
        <mesh
          filename="../meshes/hip.dae" />
      </geometry>
      <material
        name="">
        <color
          rgba="1 1 1 1" />
      </material>
    </visual>
    <collision>
      <origin rpy="1.5707963267948966 0 0" xyz="0 -0.08 0" />
      <geometry>
        <cylinder length="0.04" radius="0.046" />
      </geometry>
    </collision>
  </link>
  <joint
    name="FR_hip_joint"
    type="revolute">
    <origin
      xyz="0.1934 -0.0465 0"
      rpy="0 0 0" />
    <parent
      link="trunk" />
    <child
      link="FR_hip" />
    <axis
      xyz="1 0 0" />
    <limit
      lower="-1.0472"
      upper="1.0472"
      effort="23.7"
      velocity="30.1" />
  </joint>
  <link
    name="FR_thigh">
    <inertial>
      <origin
        xyz="-0.00374 0.0223 -0.0327"
        rpy="0 0 0" />
      <mass
        value="1.152" />
      <inertia
        ixx="0.00584"
        ixy="-8.72E-05"
        ixz="-0.000289"
        iyy="0.0058"
        iyz="-0.000808"
        izz="0.00103" />
    </inertial>
    <visual>
      <origin
        xyz="0 0 0"
        rpy="0 0 0" />
      <geometry>
        <mesh
          filename="../meshes/thigh_mirror.dae" />
      </geometry>
      <material
        name="">
        <color
          rgba="1 1 1 1" />
      </material>
    </visual>
    <collision>
      <origin rpy="0 1.5707963267948966 0" xyz="0 0 -0.1065" />
      <geometry>
        <box size="0.11 0.0245 0.034" />
      </geometry>
    </collision>
  </link>
  <joint
    name="FR_thigh_joint"
    type="revolute">
    <origin
      xyz="0 -0.0955 0"
      rpy="0 0 0" />
    <parent
      link="FR_hip" />
    <child
      link="FR_thigh" />
    <axis
      xyz="0 1 0" />
    <limit
      lower="-1.5708"
      upper="3.4907"
      effort="23.7"
      velocity="30.1" />
  </joint>
  <link
    name="FR_calf">
    <inertial>
      <origin
        xyz="0.00548 0.000975 -0.115"
        rpy="0 0 0" />
      <mass
        value="0.154" />
      <inertia
        ixx="0.00108"
        ixy="-3.4E-07"
        ixz="1.72E-05"
        iyy="0.0011"
        iyz="-8.28E-06"
        izz="3.29E-05" />
    </inertial>
    <visual>
      <origin
        xyz="0 0 0"
        rpy="0 0 0" />
      <geometry>
        <mesh
          filename="../meshes/calf_mirror.dae" />
      </geometry>
      <material
        name="">
        <color
          rgba="1 1 1 1" />
      </material>
    </visual>
    <collision>
      <origin rpy="0 -0.2 0" xyz="0.01 0 -0.06" />
      <geometry>
        <cylinder length="0.12" radius="0.013" />
      </geometry>
    </collision>
  </link>
  <joint
    name="FR_calf_joint"
    type="revolute">
    <origin
      xyz="0 0 -0.213"
      rpy="0 0 0" />
    <parent
      link="FR_thigh" />
    <child
      link="FR_calf" />
    <axis
      xyz="0 1 0" />
    <limit
      lower="-2.7227"
      upper="-0.83776"
      effort="35.55"
      velocity="20.07" />
  </joint>
  <link
    name="FR_calflower">
    <collision>
      <origin rpy="0 0 0" xyz="0 0 0" />
      <geometry>
        <cylinder length="0.065" radius="0.011" />
      </geometry>
    </collision>
  </link>
  <joint
    name="FR_calflower_joint"
    type="fixed">
    <origin
      xyz="0.020 0 -0.148"
      rpy="0 0.05 0" />
    <parent
      link="FR_calf" />
    <child
      link="FR_calflower" />
    <axis
      xyz="0 0 0" />
  </joint>
  <link
    name="FR_calflower1">
    <collision>
      <origin rpy="0 0 0" xyz="0 0 0" />
      <geometry>
        <cylinder length="0.03" radius="0.0155" />
      </geometry>
    </collision>
  </link>
  <joint
    name="FR_calflower1_joint"
    type="fixed">
    <origin
      xyz="-0.01 0 -0.04"
      rpy="0 0.48 0" />
    <parent
      link="FR_calflower" />
    <child
      link="FR_calflower1" />
    <axis
      xyz="0 0 0" />
  </joint>
  <link
    name="FR_foot">
    <inertial>
      <origin
        xyz="0 0 0"
        rpy="0 0 0" />
      <mass
        value="0.04" />
      <inertia
        ixx="9.6e-06"
        ixy="0"
        ixz="0"
        iyy="9.6e-06"
        iyz="0"
        izz="9.6e-06" />
    </inertial>
    <visual>
      <origin
        xyz="0 0 0"
        rpy="0 0 0" />
      <geometry>
        <mesh
          filename="../meshes/foot.dae" />
      </geometry>
      <material
        name="">
        <color
          rgba="1 1 1 1" />
      </material>
    </visual>
    <collision>
      <origin rpy="0 0 0" xyz="-0.002 0 0" />
      <geometry>
        <sphere radius="0.022" />
      </geometry>
    </collision>
  </link>
  <joint
    name="FR_foot_joint"
    type="fixed" >
    <origin
      xyz="0 0 -0.213"
      rpy="0 0 0" />
    <parent
      link="FR_calf" />
    <child
      link="FR_foot" />
    <axis
      xyz="0 0 0" />
  </joint>
  <link
    name="RL_hip">
    <inertial>
      <origin
        xyz="0.0054 0.00194 -0.000105"
        rpy="0 0 0" />
      <mass
        value="0.678" />
      <inertia
        ixx="0.00048"
        ixy="3.01E-06"
        ixz="-1.11E-06"
        iyy="0.000884"
        iyz="-1.42E-06"
        izz="0.000596" />
    </inertial>
    <visual>
      <origin
        xyz="0 0 0"
        rpy="0 3.1415 0" />
      <geometry>
        <mesh
          filename="../meshes/hip.dae" />
      </geometry>
      <material
        name="">
        <color
          rgba="1 1 1 1" />
      </material>
    </visual>
    <collision>
      <origin rpy="1.5707963267948966 0 0" xyz="0 0.08 0" />
      <geometry>
        <cylinder length="0.04" radius="0.046" />
      </geometry>
    </collision>
  </link>
  <joint
    name="RL_hip_joint"
    type="revolute">
    <origin
      xyz="-0.1934 0.0465 0"
      rpy="0 0 0" />
    <parent
      link="trunk" />
    <child
      link="RL_hip" />
    <axis
      xyz="1 0 0" />
    <limit
      lower="-1.0472"
      upper="1.0472"
      effort="23.7"
      velocity="30.1" />
  </joint>
  <link
    name="RL_thigh">
    <inertial>
      <origin
        xyz="-0.00374 -0.0223 -0.0327"
        rpy="0 0 0" />
      <mass
        value="1.152" />
      <inertia
        ixx="0.00584"
        ixy="8.72E-05"
        ixz="-0.000289"
        iyy="0.0058"
        iyz="0.000808"
        izz="0.00103" />
    </inertial>
    <visual>
      <origin
        xyz="0 0 0"
        rpy="0 0 0" />
      <geometry>
        <mesh
          filename="../meshes/thigh.dae" />
      </geometry>
      <material
        name="">
        <color
          rgba="1 1 1 1" />
      </material>
    </visual>
    <collision>
      <origin rpy="0 1.5707963267948966 0" xyz="0 0 -0.1065" />
      <geometry>
        <box size="0.11 0.0245 0.034" />
      </geometry>
    </collision>
  </link>
  <joint
    name="RL_thigh_joint"
    type="revolute">
    <origin
      xyz="0 0.0955 0"
      rpy="0 0 0" />
    <parent
      link="RL_hip" />
    <child
      link="RL_thigh" />
    <axis
      xyz="0 1 0" />
    <limit
      lower="-0.5236"
      upper="4.5379"
      effort="23.7"
      velocity="30.1" />
  </joint>
  <link
    name="RL_calf">
    <inertial>
      <origin
        xyz="0.00548 -0.000975 -0.115"
        rpy="0 0 0" />
      <mass
        value="0.154" />
      <inertia
        ixx="0.00108"
        ixy="3.4E-07"
        ixz="1.72E-05"
        iyy="0.0011"
        iyz="8.28E-06"
        izz="3.29E-05" />
    </inertial>
    <visual>
      <origin
        xyz="0 0 0"
        rpy="0 0 0" />
      <geometry>
        <mesh
          filename="../meshes/calf.dae" />
      </geometry>
      <material
        name="">
        <color
          rgba="1 1 1 1" />
      </material>
    </visual>
    <collision>
      <origin rpy="0 -0.2 0" xyz="0.01 0 -0.06" />
      <geometry>
        <cylinder length="0.12" radius="0.013" />
      </geometry>
    </collision>
  </link>
  <joint
    name="RL_calf_joint"
    type="revolute">
    <origin
      xyz="0 0 -0.213"
      rpy="0 0 0" />
    <parent
      link="RL_thigh" />
    <child
      link="RL_calf" />
    <axis
      xyz="0 1 0" />
    <limit
      lower="-2.7227"
      upper="-0.83776"
      effort="35.55"
      velocity="20.07" />
  </joint>
  <link
    name="RL_calflower">
    <collision>
      <origin rpy="0 0 0" xyz="0 0 0" />
      <geometry>
        <cylinder length="0.065" radius="0.011" />
      </geometry>
    </collision>
  </link>
  <joint
    name="RL_calflower_joint"
    type="fixed">
    <origin
      xyz="0.020 0 -0.148"
      rpy="0 0.05 0" />
    <parent
      link="RL_calf" />
    <child
      link="RL_calflower" />
    <axis
      xyz="0 0 0" />
  </joint>
  <link
    name="RL_calflower1">
    <collision>
      <origin rpy="0 0 0" xyz="0 0 0" />
      <geometry>
        <cylinder length="0.03" radius="0.0155" />
      </geometry>
    </collision>
  </link>
  <joint
    name="RL_calflower1_joint"
    type="fixed">
    <origin
      xyz="-0.01 0 -0.04"
      rpy="0 0.48 0" />
    <parent
      link="RL_calflower" />
    <child
      link="RL_calflower1" />
    <axis
      xyz="0 0 0" />
  </joint>
  <link
    name="RL_foot">
    <inertial>
      <origin
        xyz="0 0 0"
        rpy="0 0 0" />
      <mass
        value="0.04" />
      <inertia
        ixx="9.6e-06"
        ixy="0"
        ixz="0"
        iyy="9.6e-06"
        iyz="0"
        izz="9.6e-06" />
    </inertial>
    <visual>
      <origin
        xyz="0 0 0"
        rpy="0 0 0" />
      <geometry>
        <mesh
          filename="../meshes/foot.dae" />
      </geometry>
      <material
        name="">
        <color
          rgba="1 1 1 1" />
      </material>
    </visual>
    <collision>
      <origin rpy="0 0 0" xyz="-0.002 0 0" />
      <geometry>
        <sphere radius="0.022" />
      </geometry>
    </collision>
  </link>
  <joint
    name="RL_foot_joint"
    type="fixed" >
    <origin
      xyz="0 0 -0.213"
      rpy="0 0 0" />
    <parent
      link="RL_calf" />
    <child
      link="RL_foot" />
    <axis
      xyz="0 0 0" />
  </joint>
  <link
    name="RR_hip">
    <inertial>
      <origin
        xyz="0.0054 -0.00194 -0.000105"
        rpy="0 0 0" />
      <mass
        value="0.678" />
      <inertia
        ixx="0.00048"
        ixy="-3.01E-06"
        ixz="-1.11E-06"
        iyy="0.000884"
        iyz="1.42E-06"
        izz="0.000596" />
    </inertial>
    <visual>
      <origin
        xyz="0 0 0"
        rpy="3.1415 3.1415 0" />
      <geometry>
        <mesh
          filename="../meshes/hip.dae" />
      </geometry>
      <material
        name="">
        <color
          rgba="1 1 1 1" />
      </material>
    </visual>
    <collision>
      <origin rpy="1.5707963267948966 0 0" xyz="0 -0.08 0" />
      <geometry>
        <cylinder length="0.04" radius="0.046" />
      </geometry>
    </collision>
  </link>
  <joint
    name="RR_hip_joint"
    type="revolute">
    <origin
      xyz="-0.1934 -0.0465 0"
      rpy="0 0 0" />
    <parent
      link="trunk" />
    <child
      link="RR_hip" />
    <axis
      xyz="1 0 0" />
    <limit
      lower="-1.0472"
      upper="1.0472"
      effort="23.7"
      velocity="30.1" />
  </joint>
  <link
    name="RR_thigh">
    <inertial>
      <origin
        xyz="-0.00374 0.0223 -0.0327"
        rpy="0 0 0" />
      <mass
        value="1.152" />
      <inertia
        ixx="0.00584"
        ixy="-8.72E-05"
        ixz="-0.000289"
        iyy="0.0058"
        iyz="-0.000808"
        izz="0.00103" />
    </inertial>
    <visual>
      <origin
        xyz="0 0 0"
        rpy="0 0 0" />
      <geometry>
        <mesh
          filename="../meshes/thigh_mirror.dae" />
      </geometry>
      <material
        name="">
        <color
          rgba="1 1 1 1" />
      </material>
    </visual>
    <collision>
      <origin rpy="0 1.5707963267948966 0" xyz="0 0 -0.1065" />
      <geometry>
        <box size="0.11 0.0245 0.034" />
      </geometry>
    </collision>
  </link>
  <joint
    name="RR_thigh_joint"
    type="revolute">
    <origin
      xyz="0 -0.0955 0"
      rpy="0 0 0" />
    <parent
      link="RR_hip" />
    <child
      link="RR_thigh" />
    <axis
      xyz="0 1 0" />
    <limit
      lower="-0.5236"
      upper="4.5379"
      effort="23.7"
      velocity="30.1" />
  </joint>
  <link
    name="RR_calf">
    <inertial>
      <origin
        xyz="0.00548 0.000975 -0.115"
        rpy="0 0 0" />
      <mass
        value="0.154" />
      <inertia
        ixx="0.00108"
        ixy="-3.4E-07"
        ixz="1.72E-05"
        iyy="0.0011"
        iyz="-8.28E-06"
        izz="3.29E-05" />
    </inertial>
    <visual>
      <origin
        xyz="0 0 0"
        rpy="0 0 0" />
      <geometry>
        <mesh
          filename="../meshes/calf_mirror.dae" />
      </geometry>
      <material
        name="">
        <color
          rgba="1 1 1 1" />
      </material>
    </visual>
    <collision>
      <origin rpy="0 -0.2 0" xyz="0.01 0 -0.06" />
      <geometry>
        <cylinder length="0.12" radius="0.013" />
      </geometry>
    </collision>
  </link>
  <joint
    name="RR_calf_joint"
    type="revolute">
    <origin
      xyz="0 0 -0.213"
      rpy="0 0 0" />
    <parent
      link="RR_thigh" />
    <child
      link="RR_calf" />
    <axis
      xyz="0 1 0" />
    <limit
      lower="-2.7227"
      upper="-0.83776"
      effort="35.55"
      velocity="20.07" />
  </joint>
  <link
    name="RR_calflower">
    <collision>
      <origin rpy="0 0 0" xyz="0 0 0" />
      <geometry>
        <cylinder length="0.065" radius="0.011" />
      </geometry>
    </collision>
  </link>
  <joint
    name="RR_calflower_joint"
    type="fixed">
    <origin
      xyz="0.020 0 -0.148"
      rpy="0 0.05 0" />
    <parent
      link="RR_calf" />
    <child
      link="RR_calflower" />
    <axis
      xyz="0 0 0" />
  </joint>
  <link
    name="RR_calflower1">
    <collision>
      <origin rpy="0 0 0" xyz="0 0 0" />
      <geometry>
        <cylinder length="0.03" radius="0.0155" />
      </geometry>
    </collision>
  </link>
  <joint
    name="RR_calflower1_joint"
    type="fixed">
    <origin
      xyz="-0.01 0 -0.04"
      rpy="0 0.48 0" />
    <parent
      link="RR_calflower" />
    <child
      link="RR_calflower1" />
    <axis
      xyz="0 0 0" />
  </joint>
  <link
    name="RR_foot">
    <inertial>
      <origin
        xyz="0 0 0"
        rpy="0 0 0" />
      <mass
        value="0.04" />
      <inertia
        ixx="9.6e-06"
        ixy="0"
        ixz="0"
        iyy="9.6e-06"
        iyz="0"
        izz="9.6e-06" />
    </inertial>
    <visual>
      <origin
        xyz="0 0 0"
        rpy="0 0 0" />
      <geometry>
        <mesh
          filename="../meshes/foot.dae" />
      </geometry>
      <material
        name="">
        <color
          rgba="1 1 1 1" />
      </material>
    </visual>
    <collision>
      <origin rpy="0 0 0" xyz="-0.002 0 0" />
      <geometry>
        <sphere radius="0.022" />
      </geometry>
    </collision>
  </link>
  <joint
    name="RR_foot_joint"
    type="fixed" >
    <origin
      xyz="0 0 -0.213"
      rpy="0 0 0" />
    <parent
      link="RR_calf" />
    <child
      link="RR_foot" />
    <axis
      xyz="0 0 0" />
  </joint>
  <link
    name="imu">
    <inertial>
      <origin
        xyz="0 0 0"
        rpy="0 0 0" />
      <mass
        value="0" />
      <inertia
        ixx="0"
        ixy="0"
        ixz="0"
        iyy="0"
        iyz="0"
        izz="0" />
    </inertial>
  </link>
  <joint
    name="imu_joint"
    type="fixed">
    <origin
      xyz="-0.02557 0 0.04232"
      rpy="0 0 0" />
    <parent
      link="trunk" />
    <child
      link="imu" />
    <axis
      xyz="0 0 0" />
  </joint>
  <link
    name="radar">
    <inertial>
      <origin
        xyz="0 0 0"
        rpy="0 0 0" />
      <mass
        value="0" />
      <inertia
        ixx="0"
        ixy="0"
        ixz="0"
        iyy="0"
        iyz="0"
        izz="0" />
    </inertial>
  </link>
  <joint
    name="radar_joint"
    type="fixed">
    <origin
      xyz="0.28945 0 -0.046825"
      rpy="0 2.8782 0" />
    <parent
      link="trunk" />
    <child
      link="radar" />
    <axis
      xyz="0 0 0" />
  </joint>
<!-- 
  <link
    name="arm_base_link">
    <inertial>
      <origin
        xyz="-0.000133594636558835 6.67198653031112E-05 0.0316719411200413"
        rpy="0 0 0" />
      <mass
        value="0.422721353715926" />
      <inertia
        ixx="0.00019"
        ixy="0.00000"
        ixz="0.00000"
        iyy="0.00019"
        iyz="0.00000"
        izz="0.00020" />
    </inertial>
    <visual>
      <origin
        xyz="0 0 0"
        rpy="0 0 0" />
      <geometry>
        <mesh
          filename="../meshes/base_link.STL" />
      </geometry>
      <material
        name="">
        <color
          rgba="0.898039215686275 0.917647058823529 0.929411764705882 1" />
      </material>
    </visual>
    <collision>
      <origin
        xyz="0 0 0"
        rpy="0 0 0" />
      <geometry>
        <mesh
          filename="../meshes/base_link.STL" />
      </geometry>
    </collision>
  </link>

    <joint
    name="arm_base_joint"
    type="fixed">
    <origin
      xyz="0 0 0"
      rpy="0 0 0" />
    <parent
      link="trunk" />
    <child
      link="arm_base_link" />
    <axis
      xyz="0 0 0" />
  </joint>

  <link
    name="arm_link1">
    <inertial>
      <origin
        xyz="0.00503954826792913 -0.00774070193988318 0.0208969420816373"
        rpy="0 0 0" />
      <mass
        value="0.0968040209395549" />
      <inertia
        ixx="0.00011"
        ixy="-0.00001"
        ixz="0.00001"
        iyy="0.00005"
        iyz="-0.00001"
        izz="0.00010"/>
    </inertial>
    <visual>
      <origin
        xyz="0 0 0"
        rpy="0 0 0" />
      <geometry>
        <mesh
          filename="../meshes/link1.STL" />
      </geometry>
      <material
        name="">
        <color
          rgba="0.564705882352941 0.564705882352941 0.564705882352941 1" />
      </material>
    </visual>
    <collision>
      <origin
        xyz="0 0 0"
        rpy="0 0 0" />
      <geometry>
        <mesh
          filename="../meshes/link1.STL" />
      </geometry>
    </collision>
  </link>
  <joint
    name="arm_joint1"
    type="revolute">
    <origin
      xyz="0 0 0.0565"
      rpy="0 0 0" />
    <parent
      link="arm_base_link" />
    <child
      link="arm_link1" />
    <axis
      xyz="0 0 1" />
    <limit
      lower="-10"
      upper="10"
      effort="100"
      velocity="1000" />
  </joint>

  
  <link
    name="arm_link2">
    <inertial>
      <origin
        xyz="-0.129772605589326 -0.00135280906897206 -1.25530093963711E-05"
        rpy="0 0 0" />
      <mass
        value="1.11872105871019" />
      <inertia
        ixx="0.00058"
        ixy="0.00008"
        ixz="0.00000"
        iyy="0.01624"
        iyz="0.00000"
        izz="0.01621" />
    </inertial>
    <visual>
      <origin
        xyz="0 0 0"
        rpy="0 0 0" />
      <geometry>
        <mesh
          filename="../meshes/link2.STL" />
      </geometry>
      <material
        name="">
        <color
          rgba="0.792156862745098 0.819607843137255 0.933333333333333 1" />
      </material>
    </visual>
    <collision>
      <origin
        xyz="0 0 0"
        rpy="0 0 0" />
      <geometry>
        <mesh
          filename="../meshes/link2.STL" />
      </geometry>
    </collision>
  </link>
  <joint
    name="arm_joint2"
    type="revolute">
    <origin
      xyz="0.02 0 0.047"
      rpy="0 0 0" />
    <parent
      link="arm_link1" />
    <child
      link="arm_link2" />
    <axis
      xyz="0 1 0" />
    <limit
      lower="-10"
      upper="10"
      effort="100"
      velocity="1000" />
  </joint>
  <link
    name="arm_link3">
    <inertial>
      <origin
        xyz="0.161808413550856 0.00117234812671152 -0.0545500014865948"
        rpy="0 0 0" />
      <mass
        value="0.840824525877169" />
      <inertia
        ixx="0.00082"
        ixy="0.00008"
        ixz="-0.00074"
        iyy="0.00849"
        iyz="0.00001"
        izz="0.00834"/>
    </inertial>
    <visual>
      <origin
        xyz="0 0 0"
        rpy="0 0 0" />
      <geometry>
        <mesh
          filename="../meshes/link3.STL" />
      </geometry>
      <material
        name="">
        <color
          rgba="0.898039215686275 0.917647058823529 0.929411764705882 1" />
      </material>
    </visual>
    <collision>
      <origin
        xyz="0 0 0"
        rpy="0 0 0" />
      <geometry>
        <mesh
          filename="../meshes/link3.STL" />
      </geometry>
    </collision>
  </link>
  <joint
    name="arm_joint3"
    type="revolute">
    <origin
      xyz="-0.264 0 0"
      rpy="-3.1416 0 0" />
    <parent
      link="arm_link2" />
    <child
      link="arm_link3" />
    <axis
      xyz="0 1 0" />
    <limit
      lower="-10"
      upper="10"
      effort="100"
      velocity="1000" />
  </joint>
  <link
    name="arm_link4">
    <inertial>
      <origin
        xyz="0.0417509911034941 0.00542364535604879 -0.0333698322632074"
        rpy="0 0 0" />
      <mass
        value="0.124324803309629" />
      <inertia
        ixx="0.00022"
        ixy="-0.00002"
        ixz="-0.00009"
        iyy="0.00025"
        iyz="0.00002"
        izz="0.00017" />
    </inertial>
    <visual>
      <origin
        xyz="0 0 0"
        rpy="0 0 0" />
      <geometry>
        <mesh
          filename="../meshes/link4.STL" />
      </geometry>
      <material
        name="">
        <color
          rgba="0.792156862745098 0.819607843137255 0.933333333333333 1" />
      </material>
    </visual>
    <collision>
      <origin
        xyz="0 0 0"
        rpy="0 0 0" />
      <geometry>
        <mesh
          filename="../meshes/link4.STL" />
      </geometry>
    </collision>
  </link>
  <joint
    name="arm_joint4"
    type="revolute">
    <origin
      xyz="0.245 -5E-05 -0.06"
      rpy="0 0 0" />
    <parent
      link="arm_link3" />
    <child
      link="arm_link4" />
    <axis
      xyz="0 1 0" />
    <limit
      lower="-10"
      upper="10"
      effort="100"
      velocity="1000" />
  </joint>
  <link
    name="arm_link5">
    <inertial>
      <origin
        xyz="-8.34347586788076E-05 -1.54277362126536E-05 0.0522159141095905"
        rpy="0 0 0" />
      <mass
        value="0.636013398718113" />
      <inertia
        ixx="0.00084"
        ixy="0.00000"
        ixz="0.00007"
        iyy="0.00082"
        iyz="0.00000"
        izz="0.00026" />
    </inertial>
    <visual>
      <origin
        xyz="0 0 0"
        rpy="0 0 0" />
      <geometry>
        <mesh
          filename="../meshes/link5.STL" />
      </geometry>
      <material
        name="">
        <color
          rgba="0.698039215686274 0.698039215686274 0.698039215686274 1" />
      </material>
    </visual>
    <collision>
      <origin
        xyz="0 0 0"
        rpy="0 0 0" />
      <geometry>
        <mesh
          filename="../meshes/link5.STL" />
      </geometry>
    </collision>
  </link>
  <joint
    name="arm_joint5"
    type="revolute">
    <origin
      xyz="0.073914 5E-05 -0.083391"
      rpy="0 0 0" />
    <parent
      link="arm_link4" />
    <child
      link="arm_link5" />
    <axis
      xyz="0 0 1" />
    <limit
      lower="-10"
      upper="10"
      effort="100"
      velocity="1000" />
  </joint>
  <link
    name="arm_link6">
    <inertial>
      <origin
        xyz="0.0507223791682477 -4.87718325388323E-05 5.11083473064E-05"
        rpy="0 0 0" />
      <mass
        value="0.562622175728676" />
      <inertia
        ixx="0.00046"
        ixy="0.00000"
        ixz="0.00000"
        iyy="0.00052"
        iyz="0.00000"
        izz="0.00078" />
    </inertial>
    <visual>
      <origin
        xyz="0 0 0"
        rpy="0 0 0" />
      <geometry>
        <mesh
          filename="../meshes/link6.STL" />
      </geometry>
      <material
        name="">
        <color
          rgba="0.792156862745098 0.819607843137255 0.933333333333333 1" />
      </material>
    </visual>
    <collision>
      <origin
        xyz="0 0 0"
        rpy="0 0 0" />
      <geometry>
        <mesh
          filename="../meshes/link6.STL" />
      </geometry>
    </collision>
  </link>
  <joint
    name="arm_joint6"
    type="revolute">
    <origin
      xyz="0.025286 0 0.083391"
      rpy="3.1416 0 0" />
    <parent
      link="arm_link5" />
    <child
      link="arm_link6" />
    <axis
      xyz="1 0 0" />
    <limit
      lower="-10"
      upper="10"
      effort="100"
      velocity="1000" />
  </joint> -->

  <joint
    name="arm_base_joint"
    type="fixed">
    <origin
      xyz="0 0 0"
      rpy="0 0 0" />
    <parent
      link="trunk" />
    <child
      link="arm_link00" />
    <axis
      xyz="0 0 0" />
  </joint>
  <link
    name="arm_link00">
    <inertial>
      <origin
        xyz="-0.00973928490005031 1.8312708928633E-06 0.0410140167677137"
        rpy="0 0 0" />
      <mass
        value="0.162352169522719" />
      <inertia
        ixx="0.000226592553127906"
        ixy="-7.33974356968813E-08"
        ixz="2.13221970218123E-06"
        iyy="0.000269447877479622"
        iyz="8.15167478685076E-09"
        izz="0.000222318286704" />
    </inertial>
    <visual>
      <origin
        xyz="0 0 0"
        rpy="0 0 0" />
      <geometry>
        <mesh
          filename="../meshes/piper/base_link.STL" />
      </geometry>
      <material
        name="">
        <color
          rgba="0.792156862745098 0.819607843137255 0.933333333333333 1" />
      </material>
    </visual>
    <collision>
      <origin
        xyz="0 0 0"
        rpy="0 0 0" />
      <geometry>
        <mesh
          filename="../meshes/piper/base_link.STL" />
      </geometry>
    </collision>
  </link>
  <link
    name="arm_link01">
    <inertial>
      <origin
        xyz="0.00131676031927021 0.000310288842008364 -0.00922874512303438"
        rpy="0 0 0" />
      <mass
        value="0.0978679932242825" />
      <inertia
        ixx="7.76684558296781E-05"
        ixy="1.09084650459916E-07"
        ixz="-1.97480532432411E-06"
        iyy="9.24967780161546E-05"
        iyz="9.91284646834672E-07"
        izz="8.24589062407806E-05" />
    </inertial>
    <visual>
      <origin
        xyz="0 0 0"
        rpy="0 0 0" />
      <geometry>
        <mesh
          filename="../meshes/piper/link1.STL" />
      </geometry>
      <material
        name="">
        <color
          rgba="0.792156862745098 0.819607843137255 0.933333333333333 1" />
      </material>
    </visual>
    <collision>
      <origin
        xyz="0 0 0"
        rpy="0 0 0" />
      <geometry>
        <mesh
          filename="../meshes/piper/link1.STL" />
      </geometry>
    </collision>
  </link>

  <joint
    name="arm_joint00"
    type="revolute">
    <origin
      xyz="0 0 0.123"
      rpy="0 0 -1.5708" />
    <parent
      link="arm_link00" />
    <child
      link="arm_link01" />
    <axis
      xyz="0 0 1" />
    <limit
      lower="-2.618"
      upper="2.618"
      effort="100"
      velocity="2" />
  </joint>
  <link
    name="arm_link02">
    <inertial>
      <origin
        xyz="0.147615838821413 -0.0174259998251393 0.00175952516190707"
        rpy="0 0 0" />
      <mass
        value="0.289571136953082" />
      <inertia
        ixx="0.000150112628108228"
        ixy="8.58974959950769E-05"
        ixz="-1.07428153464285E-06"
        iyy="0.00172585302855383"
        iyz="-9.93704792239686E-07"
        izz="0.00177445942914759" />
    </inertial>
    <visual>
      <origin
        xyz="0 0 0"
        rpy="0 0 0" />
      <geometry>
        <mesh
          filename="../meshes/piper/link2.STL" />
      </geometry>
      <material
        name="">
        <color
          rgba="0.792156862745098 0.819607843137255 0.933333333333333 1" />
      </material>
    </visual>
    <collision>
      <origin
        xyz="0 0 0"
        rpy="0 0 0" />
      <geometry>
        <mesh
          filename="../meshes/piper/link2.STL" />
      </geometry>
    </collision>
  </link>
  <joint
    name="arm_joint01"
    type="revolute">
    <origin
      xyz="0 0 0"
      rpy="1.5708 -0.10095 -1.5708" />
    <parent
      link="arm_link01" />
    <child
      link="arm_link02" />
    <axis
      xyz="0 0 1" />
    <limit
      lower="0"
      upper="3.14"
      effort="100"
      velocity="2" />
  </joint>
  <link
    name="arm_link03">
    <inertial>
      <origin
        xyz="0.0156727246030052 0.104466514905741 0.000508486764144372"
        rpy="0 0 0" />
      <mass
        value="0.290583247455324" />
      <inertia
        ixx="0.000221686352136266"
        ixy="-7.57426543992343E-06"
        ixz="-6.3700062772173E-07"
        iyy="0.000100859162015934"
        iyz="-8.16202696860781E-07"
        izz="0.000241839316548946" />
    </inertial>
    <visual>
      <origin
        xyz="0 0 0"
        rpy="0 0 0" />
      <geometry>
        <mesh
          filename="../meshes/piper/link3.STL" />
      </geometry>
      <material
        name="">
        <color
          rgba="0.792156862745098 0.819607843137255 0.933333333333333 1" />
      </material>
    </visual>
    <collision>
      <origin
        xyz="0 0 0"
        rpy="0 0 0" />
      <geometry>
        <mesh
          filename="../meshes/piper/link3.STL" />
      </geometry>
    </collision>
  </link>
  <joint
    name="arm_joint02"
    type="revolute">
    <origin
      xyz="0.28503 0 0"
      rpy="0 0 1.3826" />
    <parent
      link="arm_link02" />
    <child
      link="arm_link03" />
    <axis
      xyz="0 0 1" />
    <limit
      lower="-2.967"
      upper="0"
      effort="100"
      velocity="2" />
  </joint>
  <link
    name="arm_link04">
    <inertial>
      <origin
        xyz="0.000276464622388145 -0.00102803669324853 -0.00472830700561612"
        rpy="0 0 0" />
      <mass
        value="0.127087348341362" />
      <inertia
        ixx="3.82011730423098E-05"
        ixy="-4.92358351033589E-08"
        ixz="4.89589432983109E-08"
        iyy="4.87048555222491E-05"
        iyz="6.70802942486707E-08"
        izz="4.10592077565155E-05" />
    </inertial>
    <visual>
      <origin
        xyz="0 0 0"
        rpy="0 0 0" />
      <geometry>
        <mesh
          filename="../meshes/piper/link4.STL" />
      </geometry>
      <material
        name="">
        <color
          rgba="0.792156862745098 0.819607843137255 0.933333333333333 1" />
      </material>
    </visual>
    <collision>
      <origin
        xyz="0 0 0"
        rpy="0 0 0" />
      <geometry>
        <mesh
          filename="../meshes/piper/link4.STL" />
      </geometry>
    </collision>
  </link>
  <joint
    name="arm_joint03"
    type="revolute">
    <origin
      xyz="0.021984 0.25075 0"
      rpy="-1.5708 0 0" />
    <parent
      link="arm_link03" />
    <child
      link="arm_link04" />
    <axis
      xyz="0 0 -1" />
    <limit
      lower="-1.832"
      upper="1.832"
      effort="100"
      velocity="2" />
  </joint>
  <link
    name="arm_link05">
    <inertial>
      <origin
        xyz="8.82261259100015E-05 0.056682908434204 -0.00196119077436732"
        rpy="0 0 0" />
      <mass
        value="0.144711209371719" />
      <inertia
        ixx="4.39644269159173E-05"
        ixy="-3.59214840853815E-08"
        ixz="-1.89785003257649E-08"
        iyy="5.63173857792457E-05"
        iyz="-2.15407623722543E-07"
        izz="4.88713595021005E-05" />
    </inertial>
    <visual>
      <origin
        xyz="0 0 0"
        rpy="0 0 0" />
      <geometry>
        <mesh
          filename="../meshes/piper/link5.STL" />
      </geometry>
      <material
        name="">
        <color
          rgba="0.792156862745098 0.819607843137255 0.933333333333333 1" />
      </material>
    </visual>
    <collision>
      <origin
        xyz="0 0 0"
        rpy="0 0 0" />
      <geometry>
        <mesh
          filename="../meshes/piper/link5.STL" />
      </geometry>
    </collision>
  </link>
  <joint
    name="arm_joint04"
    type="revolute">
    <origin
      xyz="0 0 0"
      rpy="1.5708 -0.087266 0" />
    <parent
      link="arm_link04" />
    <child
      link="arm_link05" />
    <axis
      xyz="0 0 1" />
    <limit
      lower="-1.22"
      upper="1.22"
      effort="100"
      velocity="2" />
  </joint>
  <link
    name="gripper_link">
    <inertial>
      <origin
        xyz="9.41121070072333E-09 0.000341209775988838 0.0342122921883722"
        rpy="0 0 0" />
      <mass
        value="0.150196458571266" />
      <inertia
        ixx="4.31750564711759E-05"
        ixy="-2.21295720427027E-08"
        ixz="-3.27825836857102E-12"
        iyy="9.99756357365307E-05"
        iyz="1.10337380549335E-07"
        izz="0.000118282295533688" />
    </inertial>
    <visual>
      <origin
        xyz="0 0 0"
        rpy="0 0 0" />
      <geometry>
        <mesh
          filename="../meshes/piper/link6.STL" />
      </geometry>
      <material
        name="">
        <color
          rgba="0.792156862745098 0.819607843137255 0.933333333333333 1" />
      </material>
    </visual>
    <collision>
      <origin
        xyz="0 0 0"
        rpy="0 0 0" />
      <geometry>
        <mesh
          filename="../meshes/piper/link6.STL" />
      </geometry>
    </collision>
  </link>
  <joint
    name="arm_joint05"
    type="revolute">
    <origin
      xyz="0 0.091 0.0014165"
      rpy="-1.5708 -1.5708 0" />
    <parent
      link="arm_link05" />
    <child
      link="gripper_link" />
    <axis
      xyz="0 0 -1" />
    <limit
      lower="-3.14"
      upper="3.14"
      effort="100"
      velocity="2" />
  </joint>

  <link
    name="gripper_link_right">
    <inertial>
      <origin
        xyz="-0.000277795893713934 -0.046767350270289 -0.00921029791141448"
        rpy="0 0 0" />
      <mass
        value="0.0264822500394006" />
      <inertia
        ixx="9.99782519244544E-06"
        ixy="-1.57547595978589E-07"
        ixz="-2.71355785017816E-08"
        iyy="6.17952364356547E-06"
        iyz="-1.58939504838734E-06"
        izz="1.42102253390315E-05" />
    </inertial>
    <visual>
      <origin
        xyz="0 0 0"
        rpy="0 0 0" />
      <geometry>
        <mesh
          filename="../meshes/piper/link7.STL" />
      </geometry>
      <material
        name="">
        <color
          rgba="0.792156862745098 0.819607843137255 0.933333333333333 1" />
      </material>
    </visual>
    <collision>
      <origin
        xyz="0 0 0"
        rpy="0 0 0" />
      <geometry>
        <mesh
          filename="../meshes/piper/link7.STL" />
      </geometry>
    </collision>
  </link>
  <joint
    name="arm_joint06"
    type="revolute">
    <origin
      xyz="0 0 0.13503"
      rpy="1.5708 0 1.5708" />
    <parent
      link="gripper_link" />
    <child
      link="gripper_link_right" />
    <axis
      xyz="0 0 -1" />
    <limit
      lower="0.0"
      upper="0.04"
      effort="100"
      velocity="2" />
  </joint>

  <link
    name="gripper_link_left">
    <inertial>
      <origin
        xyz="0.000277795911672651 0.0467673513153836 -0.00921029799058583"
        rpy="0 0 0" />
      <mass
        value="0.0264822490707451" />
      <inertia
        ixx="9.99782474142963E-06"
        ixy="-1.57547666236405E-07"
        ixz="2.71355834243046E-08"
        iyy="6.17952362333486E-06"
        iyz="1.58939503259658E-06"
        izz="1.42102248648757E-05" />
    </inertial>
    <visual>
      <origin
        xyz="0 0 0"
        rpy="0 0 0" />
      <geometry>
        <mesh
          filename="../meshes/piper/link8.STL" />
      </geometry>
      <material
        name="">
        <color
          rgba="0.792156862745098 0.819607843137255 0.933333333333333 1" />
      </material>
    </visual>
    <collision>
      <origin
        xyz="0 0 0"
        rpy="0 0 0" />
      <geometry>
        <mesh
          filename="../meshes/piper/link8.STL" />
      </geometry>
    </collision>
  </link>
  <joint
    name="arm_joint07"
    type="revolute">
    <origin
      xyz="0 0 0.13503"
      rpy="-1.5708 0 1.5708" />
    <parent
      link="gripper_link" />
    <child
      link="gripper_link_left" />
    <axis
      xyz="0 0 1" />
    <limit
      lower="-0.04"
      upper="0.0"
      effort="100"
      velocity="2" />
  </joint>
  <link name="link_ee">
    <inertial>
      <origin
        xyz="0 0 0"
        rpy="0 0 0" />
      <mass
        value="0.0264822500394006" />
      <inertia
        ixx="9.99782519244544E-06"
        ixy="-1.57547595978589E-07"
        ixz="-2.71355785017816E-08"
        iyy="6.17952364356547E-06"
        iyz="-1.58939504838734E-06"
        izz="1.42102253390315E-05" />
    </inertial>
    <visual>
      <origin
        xyz="0 0 0"
        rpy="0 0 0" />
      <material
        name="">
        <color
          rgba="0.792156862745098 0.819607843137255 0.933333333333333 1" />
      </material>
    </visual>
    <collision>
      <origin
        xyz="0 0 0"
        rpy="0 0 0" />
    </collision>
  </link>
  <joint
    name="joint_ee"
    type="fixed">
    <origin
      xyz="0 0 0.10"
      rpy="-1.5708 -1.5708 0" />
    <parent
      link="gripper_link" />
    <child
      link="link_ee" />
    <axis
      xyz="0 0 0" />
  </joint>
</robot>